Workbook
Name projectRemainDaysTitle: #REF!
Name projectRemainWorkTitle: #REF!
Name projectRemainWorkVal: #REF!
Name projectNameTitle: #REF!
Name projectWorkVal: #REF!
Name projectStartTitle: #REF!
Name projectManagerTitle: #REF!
Name task: #REF!
Name projectDurationTitle: #REF!
Name projectRemainDaysVal: #REF!
Name projectRemainWeeksTitle: #REF!
Name projectDurationVal: #REF!
Name projectWorkTitle: #REF!
Name projectProgressVal: #REF!
Name projectFinishVal: #REF!
Name projectStartVal: #REF!
Name projectCostTitle: #REF!
Name projectCostVal: #REF!
Name MODULO2: PRESUPUESTO!$A$43:$G$102
Name projectProgressTitle: #REF!
Name projectSummaryTitle: #REF!
Name MODULO1: PRESUPUESTO!$A$10:$G$42
Name gantt: #REF!
Name MODULO3: PRESUPUESTO!$A$103:$F$128
Name projectNameVal: #REF!
Name projectRemainWeeksVal: #REF!
Name projectFinishTitle: #REF!
Name projectManagerVal: #REF!

Sheet TRANSGOOGLE
A1: translate (contact in English please) | B1: traducir (contactar en inglés, por favor)

Sheet GENERADORES
A1: GENERADORES DE VOLUMEN · MEMORIA DE CUANTIFICACIÓN
A2: PROYECTO | C2: =CARATULA!$C$10
A3: CLIENTE | C3: =CARATULA!$C$12
A4: UBICACIÓN | C4: =CARATULA!$C$14
A5: EMPRESA | C5: =CARATULA!$C$19
A6: FOLIO | B6: ='NORMA BIM'!$H$16
A7: Es a la cantidad lo que la tarjeta de precios unitarios es al precio: aquí nace el número, no se escribe a mano.
A9: CLAVE DEL CONCEPTO | B9: MÓDULO | C9: ELEMENTO / UBICACIÓN | D9: EJE O TRAMO | E9: LARGO | F9: ANCHO | G9: ALTO / ESP. | H9: No. | I9: VOLUMEN | J9: UNIDAD | K9: FUENTE / SUPUESTO | L9: DESCRIPCIÓN DEL CONCEPTO | M9: CANTIDAD EN PRESUPUESTO | N9: DIFERENCIA
A10: DEM5029 | B10: {=IF($A10="","",IFERROR(INDEX(PRESUPUESTO!$N$10:$N$262,MATCH($A10,PRESUPUESTO!$A$10:$A$262,0)),""))} | C10: Muro interior central longitudinal | D10: — | E10: 3.85 | F10: 0.35 | G10: 3.4 | H10: 1 | I10: =E10*F10*G10*H10 | J10: {=IF($A10="","",IFERROR(INDEX(PRESUPUESTO!$D$10:$D$174,MATCH($A10&"|"&$B10,PRESUPUESTO!$O$10:$O$174,0)),"⚠"))} | K10: {=IF($A10="","",IFERROR(INDEX(PRESUPUESTO!$C$10:$C$174,MATCH($A10&"|"&$B10,PRESUPUESTO!$O$10:$O$174,0)),""))} | L10: {=IF($A10="","",IFERROR(INDEX(PRESUPUESTO!$B$10:$B$174,MATCH($A10,PRESUPUESTO!$A$10:$A$174,0)),"⚠ clave no existe"))} | M10: {=IF($A10="","",IFERROR(INDEX(PRESUPUESTO!$C$10:$C$262,MATCH($A10,PRESUPUESTO!$A$10:$A$262,0)),""))} | N10: =IF($A10="","",IFERROR(SUMIF($A$10:$A$509,$A10,$I$10:$I$509)-$M10,""))
A11: DEM5029 | B11: {=IF($A11="","",IFERROR(INDEX(PRESUPUESTO!$N$10:$N$262,MATCH($A11,PRESUPUESTO!$A$10:$A$262,0)),""))} | C11: Muro interior transversal 1 | D11: — | E11: 7.53 | F11: 0.2 | G11: 3.4 | H11: 1 | I11: =E11*F11*G11*H11 | J11: {=IF($A11="","",IFERROR(INDEX(PRESUPUESTO!$D$10:$D$174,MATCH($A11&"|"&$B11,PRESUPUESTO!$O$10:$O$174,0)),"⚠"))} | K11: {=IF($A11="","",IFERROR(INDEX(PRESUPUESTO!$C$10:$C$174,MATCH($A11&"|"&$B11,PRESUPUESTO!$O$10:$O$174,0)),""))} | L11: {=IF($A11="","",IFERROR(INDEX(PRESUPUESTO!$B$10:$B$174,MATCH($A11,PRESUPUESTO!$A$10:$A$174,0)),"⚠ clave no existe"))} | M11: {=IF($A11="","",IFERROR(INDEX(PRESUPUESTO!$C$10:$C$262,MATCH($A11,PRESUPUESTO!$A$10:$A$262,0)),""))} | N11: =IF($A11="","",IFERROR(SUMIF($A$10:$A$509,$A11,$I$10:$I$509)-$M11,""))
A12: DEM5029 | B12: {=IF($A12="","",IFERROR(INDEX(PRESUPUESTO!$N$10:$N$262,MATCH($A12,PRESUPUESTO!$A$10:$A$262,0)),""))} | C12: Muro interior transversal 2 | D12: — | E12: 7.53 | F12: 0.23 | G12: 3.4 | H12: 1 | I12: =E12*F12*G12*H12 | J12: {=IF($A12="","",IFERROR(INDEX(PRESUPUESTO!$D$10:$D$174,MATCH($A12&"|"&$B12,PRESUPUESTO!$O$10:$O$174,0)),"⚠"))} | K12: {=IF($A12="","",IFERROR(INDEX(PRESUPUESTO!$C$10:$C$174,MATCH($A12&"|"&$B12,PRESUPUESTO!$O$10:$O$174,0)),""))} | L12: {=IF($A12="","",IFERROR(INDEX(PRESUPUESTO!$B$10:$B$174,MATCH($A12,PRESUPUESTO!$A$10:$A$174,0)),"⚠ clave no existe"))} | M12: {=IF($A12="","",IFERROR(INDEX(PRESUPUESTO!$C$10:$C$262,MATCH($A12,PRESUPUESTO!$A$10:$A$262,0)),""))} | N12: =IF($A12="","",IFERROR(SUMIF($A$10:$A$509,$A12,$I$10:$I$509)-$M12,""))
A13: DEM5029 | B13: {=IF($A13="","",IFERROR(INDEX(PRESUPUESTO!$N$10:$N$262,MATCH($A13,PRESUPUESTO!$A$10:$A$262,0)),""))} | C13: Muro interior transversal 3 | D13: — | E13: 7.53 | F13: 0.2 | G13: 3.4 | H13: 1 | I13: =E13*F13*G13*H13 | J13: {=IF($A13="","",IFERROR(INDEX(PRESUPUESTO!$D$10:$D$174,MATCH($A13&"|"&$B13,PRESUPUESTO!$O$10:$O$174,0)),"⚠"))} | K13: {=IF($A13="","",IFERROR(INDEX(PRESUPUESTO!$C$10:$C$174,MATCH($A13&"|"&$B13,PRESUPUESTO!$O$10:$O$174,0)),""))} | L13: {=IF($A13="","",IFERROR(INDEX(PRESUPUESTO!$B$10:$B$174,MATCH($A13,PRESUPUESTO!$A$10:$A$174,0)),"⚠ clave no existe"))} | M13: {=IF($A13="","",IFERROR(INDEX(PRESUPUESTO!$C$10:$C$262,MATCH($A13,PRESUPUESTO!$A$10:$A$262,0)),""))} | N13: =IF($A13="","",IFERROR(SUMIF($A$10:$A$509,$A13,$I$10:$I$509)-$M13,""))
A14: DEM5029 | B14: {=IF($A14="","",IFERROR(INDEX(PRESUPUESTO!$N$10:$N$262,MATCH($A14,PRESUPUESTO!$A$10:$A$262,0)),""))} | C14: Muros interiores zona inferior | D14: — | E14: 2.05 | F14: 0.88 | G14: 3.4 | H14: 1 | I14: =E14*F14*G14*H14 | J14: {=IF($A14="","",IFERROR(INDEX(PRESUPUESTO!$D$10:$D$174,MATCH($A14&"|"&$B14,PRESUPUESTO!$O$10:$O$174,0)),"⚠"))} | K14: {=IF($A14="","",IFERROR(INDEX(PRESUPUESTO!$C$10:$C$174,MATCH($A14&"|"&$B14,PRESUPUESTO!$O$10:$O$174,0)),""))} | L14: {=IF($A14="","",IFERROR(INDEX(PRESUPUESTO!$B$10:$B$174,MATCH($A14,PRESUPUESTO!$A$10:$A$174,0)),"⚠ clave no existe"))} | M14: {=IF($A14="","",IFERROR(INDEX(PRESUPUESTO!$C$10:$C$262,MATCH($A14,PRESUPUESTO!$A$10:$A$262,0)),""))} | N14: =IF($A14="","",IFERROR(SUMIF($A$10:$A$509,$A14,$I$10:$I$509)-$M14,""))
A15: DEM5029 | B15: {=IF($A15="","",IFERROR(INDEX(PRESUPUESTO!$N$10:$N$262,MATCH($A15,PRESUPUESTO!$A$10:$A$262,0)),""))} | C15: Muro de fachada a paso de servidumbre | D15: — | E15: 7.53 | F15: 0.2 | G15: 3.4 | H15: 1 | I15: =E15*F15*G15*H15 | J15: {=IF($A15="","",IFERROR(INDEX(PRESUPUESTO!$D$10:$D$174,MATCH($A15&"|"&$B15,PRESUPUESTO!$O$10:$O$174,0)),"⚠"))} | K15: {=IF($A15="","",IFERROR(INDEX(PRESUPUESTO!$C$10:$C$174,MATCH($A15&"|"&$B15,PRESUPUESTO!$O$10:$O$174,0)),""))} | L15: {=IF($A15="","",IFERROR(INDEX(PRESUPUESTO!$B$10:$B$174,MATCH($A15,PRESUPUESTO!$A$10:$A$174,0)),"⚠ clave no existe"))} | M15: {=IF($A15="","",IFERROR(INDEX(PRESUPUESTO!$C$10:$C$262,MATCH($A15,PRESUPUESTO!$A$10:$A$262,0)),""))} | N15: =IF($A15="","",IFERROR(SUMIF($A$10:$A$509,$A15,$I$10:$I$509)-$M15,""))
A16: DEM5029 | B16: {=IF($A16="","",IFERROR(INDEX(PRESUPUESTO!$N$10:$N$262,MATCH($A16,PRESUPUESTO!$A$10:$A$262,0)),""))} | C16: Muro posterior contra patio propio | D16: — | E16: 7.53 | F16: 0.16 | G16: 3.4 | H16: 1 | I16: =E16*F16*G16*H16 | J16: {=IF($A16="","",IFERROR(INDEX(PRESUPUESTO!$D$10:$D$174,MATCH($A16&"|"&$B16,PRESUPUESTO!$O$10:$O$174,0)),"⚠"))} | K16: {=IF($A16="","",IFERROR(INDEX(PRESUPUESTO!$C$10:$C$174,MATCH($A16&"|"&$B16,PRESUPUESTO!$O$10:$O$174,0)),""))} | L16: {=IF($A16="","",IFERROR(INDEX(PRESUPUESTO!$B$10:$B$174,MATCH($A16,PRESUPUESTO!$A$10:$A$174,0)),"⚠ clave no existe"))} | M16: {=IF($A16="","",IFERROR(INDEX(PRESUPUESTO!$C$10:$C$262,MATCH($A16,PRESUPUESTO!$A$10:$A$262,0)),""))} | N16: =IF($A16="","",IFERROR(SUMIF($A$10:$A$509,$A16,$I$10:$I$509)-$M16,""))
A17: DEM5030 | B17: {=IF($A17="","",IFERROR(INDEX(PRESUPUESTO!$N$10:$N$262,MATCH($A17,PRESUPUESTO!$A$10:$A$262,0)),""))} | C17: Losa de cubierta de la casa actual | D17: Zona A | E17: 7.93 | F17: 6.36 | G17: 0.12 | H17: 1 | I17: =E17*F17*G17*H17 | J17: {=IF($A17="","",IFERROR(INDEX(PRESUPUESTO!$D$10:$D$174,MATCH($A17&"|"&$B17,PRESUPUESTO!$O$10:$O$174,0)),"⚠"))} | K17: {=IF($A17="","",IFERROR(INDEX(PRESUPUESTO!$C$10:$C$174,MATCH($A17&"|"&$B17,PRESUPUESTO!$O$10:$O$174,0)),""))} | L17: {=IF($A17="","",IFERROR(INDEX(PRESUPUESTO!$B$10:$B$174,MATCH($A17,PRESUPUESTO!$A$10:$A$174,0)),"⚠ clave no existe"))} | M17: {=IF($A17="","",IFERROR(INDEX(PRESUPUESTO!$C$10:$C$262,MATCH($A17,PRESUPUESTO!$A$10:$A$262,0)),""))} | N17: =IF($A17="","",IFERROR(SUMIF($A$10:$A$509,$A17,$I$10:$I$509)-$M17,""))
A18: DEM5031 | B18: {=IF($A18="","",IFERROR(INDEX(PRESUPUESTO!$N$10:$N$262,MATCH($A18,PRESUPUESTO!$A$10:$A$262,0)),""))} | C18: Concreto pobre del patio | D18: Zona B | E18: 7.93 | F18: 3.69 | G18: 0.08 | H18: 1 | I18: =E18*F18*G18*H18 | J18: {=IF($A18="","",IFERROR(INDEX(PRESUPUESTO!$D$10:$D$174,MATCH($A18&"|"&$B18,PRESUPUESTO!$O$10:$O$174,0)),"⚠"))} | K18: {=IF($A18="","",IFERROR(INDEX(PRESUPUESTO!$C$10:$C$174,MATCH($A18&"|"&$B18,PRESUPUESTO!$O$10:$O$174,0)),""))} | L18: {=IF($A18="","",IFERROR(INDEX(PRESUPUESTO!$B$10:$B$174,MATCH($A18,PRESUPUESTO!$A$10:$A$174,0)),"⚠ clave no existe"))} | M18: {=IF($A18="","",IFERROR(INDEX(PRESUPUESTO!$C$10:$C$262,MATCH($A18,PRESUPUESTO!$A$10:$A$262,0)),""))} | N18: =IF($A18="","",IFERROR(SUMIF($A$10:$A$509,$A18,$I$10:$I$509)-$M18,""))
A19: EXV3018 | B19: {=IF($A19="","",IFERROR(INDEX(PRESUPUESTO!$N$10:$N$262,MATCH($A19,PRESUPUESTO!$A$10:$A$262,0)),""))} | C19: Trinchera CT-1 colindancia | D19: ES-07 | E19: 48.55 | F19: 0.2 | G19: 0.4 | H19: 1 | I19: =E19*F19*G19*H19 | J19: {=IF($A19="","",IFERROR(INDEX(PRESUPUESTO!$D$10:$D$174,MATCH($A19&"|"&$B19,PRESUPUESTO!$O$10:$O$174,0)),"⚠"))} | K19: {=IF($A19="","",IFERROR(INDEX(PRESUPUESTO!$C$10:$C$174,MATCH($A19&"|"&$B19,PRESUPUESTO!$O$10:$O$174,0)),""))} | L19: {=IF($A19="","",IFERROR(INDEX(PRESUPUESTO!$B$10:$B$174,MATCH($A19,PRESUPUESTO!$A$10:$A$174,0)),"⚠ clave no existe"))} | M19: {=IF($A19="","",IFERROR(INDEX(PRESUPUESTO!$C$10:$C$262,MATCH($A19,PRESUPUESTO!$A$10:$A$262,0)),""))} | N19: =IF($A19="","",IFERROR(SUMIF($A$10:$A$509,$A19,$I$10:$I$509)-$M19,""))
A20: EXV3018 | B20: {=IF($A20="","",IFERROR(INDEX(PRESUPUESTO!$N$10:$N$262,MATCH($A20,PRESUPUESTO!$A$10:$A$262,0)),""))} | C20: Trinchera CT-1 central | D20: ES-07 | E20: 40.55 | F20: 0.2 | G20: 0.4 | H20: 1 | I20: =E20*F20*G20*H20 | J20: {=IF($A20="","",IFERROR(INDEX(PRESUPUESTO!$D$10:$D$174,MATCH($A20&"|"&$B20,PRESUPUESTO!$O$10:$O$174,0)),"⚠"))} | K20: {=IF($A20="","",IFERROR(INDEX(PRESUPUESTO!$C$10:$C$174,MATCH($A20&"|"&$B20,PRESUPUESTO!$O$10:$O$174,0)),""))} | L20: {=IF($A20="","",IFERROR(INDEX(PRESUPUESTO!$B$10:$B$174,MATCH($A20,PRESUPUESTO!$A$10:$A$174,0)),"⚠ clave no existe"))} | M20: {=IF($A20="","",IFERROR(INDEX(PRESUPUESTO!$C$10:$C$262,MATCH($A20,PRESUPUESTO!$A$10:$A$262,0)),""))} | N20: =IF($A20="","",IFERROR(SUMIF($A$10:$A$509,$A20,$I$10:$I$509)-$M20,""))
A21: EXV3019 | B21: {=IF($A21="","",IFERROR(INDEX(PRESUPUESTO!$N$10:$N$262,MATCH($A21,PRESUPUESTO!$A$10:$A$262,0)),""))} | C21: Rebaje de terreno mejorado | D21: Zona B | E21: 7.93 | F21: 3.69 | G21: 0.2 | H21: 1 | I21: =E21*F21*G21*H21 | J21: {=IF($A21="","",IFERROR(INDEX(PRESUPUESTO!$D$10:$D$174,MATCH($A21&"|"&$B21,PRESUPUESTO!$O$10:$O$174,0)),"⚠"))} | K21: {=IF($A21="","",IFERROR(INDEX(PRESUPUESTO!$C$10:$C$174,MATCH($A21&"|"&$B21,PRESUPUESTO!$O$10:$O$174,0)),""))} | L21: {=IF($A21="","",IFERROR(INDEX(PRESUPUESTO!$B$10:$B$174,MATCH($A21,PRESUPUESTO!$A$10:$A$174,0)),"⚠ clave no existe"))} | M21: {=IF($A21="","",IFERROR(INDEX(PRESUPUESTO!$C$10:$C$262,MATCH($A21,PRESUPUESTO!$A$10:$A$262,0)),""))} | N21: =IF($A21="","",IFERROR(SUMIF($A$10:$A$509,$A21,$I$10:$I$509)-$M21,""))
... A31: ALB08216 | B31: {=IF($A31="","",IFERROR(INDEX(PRESUPUESTO!$N$10:$N$262,MATCH($A31,PRESUPUESTO!$A$10:$A$262,0)),""))} | C31: K-1 castillos · nivel 1 | D31: ES-07 N-2 | E31: 72.9 | F31: 1 | G31: 1 | H31: 1 | I31: =E31*F31*G31*H31 | J31: {=IF($A31="","",IFERROR(INDEX(PRESUPUESTO!$D$10:$D$174,MATCH($A31&"|"&$B31,PRESUPUESTO!$O$10:$O$174,0)),"⚠"))} | K31: {=IF($A31="","",IFERROR(INDEX(PRESUPUESTO!$C$10:$C$174,MATCH($A31&"|"&$B31,PRESUPUESTO!$O$10:$O$174,0)),""))} | L31: {=IF($A31="","",IFERROR(INDEX(PRESUPUESTO!$B$10:$B$174,MATCH($A31,PRESUPUESTO!$A$10:$A$174,0)),"⚠ clave no existe"))} | M31: {=IF($A31="","",IFERROR(INDEX(PRESUPUESTO!$C$10:$C$262,MATCH($A31,PRESUPUESTO!$A$10:$A$262,0)),""))} | N31: =IF($A31="","",IFERROR(SUMIF($A$10:$A$509,$A31,$I$10:$I$509)-$M31,""))
B32: {=IF($A32="","",IFERROR(INDEX(PRESUPUESTO!$N$10:$N$262,MATCH($A32,PRESUPUESTO!$A$10:$A$262,0)),""))} | J32: {=IF($A32="","",IFERROR(INDEX(PRESUPUESTO!$D$10:$D$174,MATCH($A32&"|"&$B32,PRESUPUESTO!$O$10:$O$174,0)),"⚠"))} | K32: {=IF($A32="","",IFERROR(INDEX(PRESUPUESTO!$C$10:$C$174,MATCH($A32&"|"&$B32,PRESUPUESTO!$O$10:$O$174,0)),""))} | L32: {=IF($A32="","",IFERROR(INDEX(PRESUPUESTO!$B$10:$B$174,MATCH($A32,PRESUPUESTO!$A$10:$A$174,0)),"⚠ clave no existe"))} | M32: {=IF($A32="","",IFERROR(INDEX(PRESUPUESTO!$C$10:$C$262,MATCH($A32,PRESUPUESTO!$A$10:$A$262,0)),""))} | N32: =IF($A32="","",IFERROR(SUMIF($A$10:$A$509,$A32,$I$10:$I$509)-$M32,""))
A33: VOLUMEN ACUMULADO POR CLAVE · esto es lo que lee la columna CANTIDAD del PRESUPUESTO | B33: {=IF($A33="","",IFERROR(INDEX(PRESUPUESTO!$N$10:$N$262,MATCH($A33,PRESUPUESTO!$A$10:$A$262,0)),""))} | J33: {=IF($A33="","",IFERROR(INDEX(PRESUPUESTO!$D$10:$D$174,MATCH($A33&"|"&$B33,PRESUPUESTO!$O$10:$O$174,0)),"⚠"))} | K33: {=IF($A33="","",IFERROR(INDEX(PRESUPUESTO!$C$10:$C$174,MATCH($A33&"|"&$B33,PRESUPUESTO!$O$10:$O$174,0)),""))} | L33: {=IF($A33="","",IFERROR(INDEX(PRESUPUESTO!$B$10:$B$174,MATCH($A33,PRESUPUESTO!$A$10:$A$174,0)),"⚠ clave no existe"))} | M33: {=IF($A33="","",IFERROR(INDEX(PRESUPUESTO!$C$10:$C$262,MATCH($A33,PRESUPUESTO!$A$10:$A$262,0)),""))} | N33: =IF($A33="","",IFERROR(SUMIF($A$10:$A$509,$A33,$I$10:$I$509)-$M33,""))
A34: CLAVE | B34: {=IF($A34="","",IFERROR(INDEX(PRESUPUESTO!$N$10:$N$262,MATCH($A34,PRESUPUESTO!$A$10:$A$262,0)),""))} | C34: CONCEPTO | I34: VOLUMEN | J34: {=IF($A34="","",IFERROR(INDEX(PRESUPUESTO!$D$10:$D$174,MATCH($A34&"|"&$B34,PRESUPUESTO!$O$10:$O$174,0)),"⚠"))} | K34: {=IF($A34="","",IFERROR(INDEX(PRESUPUESTO!$C$10:$C$174,MATCH($A34&"|"&$B34,PRESUPUESTO!$O$10:$O$174,0)),""))} | L34: {=IF($A34="","",IFERROR(INDEX(PRESUPUESTO!$B$10:$B$174,MATCH($A34,PRESUPUESTO!$A$10:$A$174,0)),"⚠ clave no existe"))} | M34: {=IF($A34="","",IFERROR(INDEX(PRESUPUESTO!$C$10:$C$262,MATCH($A34,PRESUPUESTO!$A$10:$A$262,0)),""))} | N34: =IF($A34="","",IFERROR(SUMIF($A$10:$A$509,$A34,$I$10:$I$509)-$M34,""))
A35: ALB08216 | B35: {=IF($A35="","",IFERROR(INDEX(PRESUPUESTO!$N$10:$N$262,MATCH($A35,PRESUPUESTO!$A$10:$A$262,0)),""))} | C35: {=IFERROR(INDEX(PRESUPUESTO!$B$10:$B$204,MATCH($A35&"|"&$B35,PRESUPUESTO!$O$10:$O$204,0)),"⚠ no existe en ese módulo")} | I35: =SUMIFS($I$10:$I$31,$A$10:$A$31,$A35,$B$10:$B$31,$B35) | J35: {=IF($A35="","",IFERROR(INDEX(PRESUPUESTO!$D$10:$D$174,MATCH($A35&"|"&$B35,PRESUPUESTO!$O$10:$O$174,0)),"⚠"))} | K35: {=IF($A35="","",IFERROR(INDEX(PRESUPUESTO!$C$10:$C$174,MATCH($A35&"|"&$B35,PRESUPUESTO!$O$10:$O$174,0)),""))} | L35: {=IF($A35="","",IFERROR(INDEX(PRESUPUESTO!$B$10:$B$174,MATCH($A35,PRESUPUESTO!$A$10:$A$174,0)),"⚠ clave no existe"))} | M35: {=IF($A35="","",IFERROR(INDEX(PRESUPUESTO!$C$10:$C$262,MATCH($A35,PRESUPUESTO!$A$10:$A$262,0)),""))} | N35: =IF($A35="","",IFERROR(SUMIF($A$10:$A$509,$A35,$I$10:$I$509)-$M35,""))
A36: ALB08216 | B36: {=IF($A36="","",IFERROR(INDEX(PRESUPUESTO!$N$10:$N$262,MATCH($A36,PRESUPUESTO!$A$10:$A$262,0)),""))} | C36: {=IFERROR(INDEX(PRESUPUESTO!$B$10:$B$204,MATCH($A36&"|"&$B36,PRESUPUESTO!$O$10:$O$204,0)),"⚠ no existe en ese módulo")} | I36: =SUMIFS($I$10:$I$31,$A$10:$A$31,$A36,$B$10:$B$31,$B36) | J36: {=IF($A36="","",IFERROR(INDEX(PRESUPUESTO!$D$10:$D$174,MATCH($A36&"|"&$B36,PRESUPUESTO!$O$10:$O$174,0)),"⚠"))} | K36: {=IF($A36="","",IFERROR(INDEX(PRESUPUESTO!$C$10:$C$174,MATCH($A36&"|"&$B36,PRESUPUESTO!$O$10:$O$174,0)),""))} | L36: {=IF($A36="","",IFERROR(INDEX(PRESUPUESTO!$B$10:$B$174,MATCH($A36,PRESUPUESTO!$A$10:$A$174,0)),"⚠ clave no existe"))} | M36: {=IF($A36="","",IFERROR(INDEX(PRESUPUESTO!$C$10:$C$262,MATCH($A36,PRESUPUESTO!$A$10:$A$262,0)),""))} | N36: =IF($A36="","",IFERROR(SUMIF($A$10:$A$509,$A36,$I$10:$I$509)-$M36,""))
A37: ALB08219 | B37: {=IF($A37="","",IFERROR(INDEX(PRESUPUESTO!$N$10:$N$262,MATCH($A37,PRESUPUESTO!$A$10:$A$262,0)),""))} | C37: {=IFERROR(INDEX(PRESUPUESTO!$B$10:$B$204,MATCH($A37&"|"&$B37,PRESUPUESTO!$O$10:$O$204,0)),"⚠ no existe en ese módulo")} | I37: =SUMIFS($I$10:$I$31,$A$10:$A$31,$A37,$B$10:$B$31,$B37) | J37: {=IF($A37="","",IFERROR(INDEX(PRESUPUESTO!$D$10:$D$174,MATCH($A37&"|"&$B37,PRESUPUESTO!$O$10:$O$174,0)),"⚠"))} | K37: {=IF($A37="","",IFERROR(INDEX(PRESUPUESTO!$C$10:$C$174,MATCH($A37&"|"&$B37,PRESUPUESTO!$O$10:$O$174,0)),""))} | L37: {=IF($A37="","",IFERROR(INDEX(PRESUPUESTO!$B$10:$B$174,MATCH($A37,PRESUPUESTO!$A$10:$A$174,0)),"⚠ clave no existe"))} | M37: {=IF($A37="","",IFERROR(INDEX(PRESUPUESTO!$C$10:$C$262,MATCH($A37,PRESUPUESTO!$A$10:$A$262,0)),""))} | N37: =IF($A37="","",IFERROR(SUMIF($A$10:$A$509,$A37,$I$10:$I$509)-$M37,""))
A38: ALB08219 | B38: {=IF($A38="","",IFERROR(INDEX(PRESUPUESTO!$N$10:$N$262,MATCH($A38,PRESUPUESTO!$A$10:$A$262,0)),""))} | C38: {=IFERROR(INDEX(PRESUPUESTO!$B$10:$B$204,MATCH($A38&"|"&$B38,PRESUPUESTO!$O$10:$O$204,0)),"⚠ no existe en ese módulo")} | I38: =SUMIFS($I$10:$I$31,$A$10:$A$31,$A38,$B$10:$B$31,$B38) | J38: {=IF($A38="","",IFERROR(INDEX(PRESUPUESTO!$D$10:$D$174,MATCH($A38&"|"&$B38,PRESUPUESTO!$O$10:$O$174,0)),"⚠"))} | K38: {=IF($A38="","",IFERROR(INDEX(PRESUPUESTO!$C$10:$C$174,MATCH($A38&"|"&$B38,PRESUPUESTO!$O$10:$O$174,0)),""))} | L38: {=IF($A38="","",IFERROR(INDEX(PRESUPUESTO!$B$10:$B$174,MATCH($A38,PRESUPUESTO!$A$10:$A$174,0)),"⚠ clave no existe"))} | M38: {=IF($A38="","",IFERROR(INDEX(PRESUPUESTO!$C$10:$C$262,MATCH($A38,PRESUPUESTO!$A$10:$A$262,0)),""))} | N38: =IF($A38="","",IFERROR(SUMIF($A$10:$A$509,$A38,$I$10:$I$509)-$M38,""))
A39: ALB08224 | B39: {=IF($A39="","",IFERROR(INDEX(PRESUPUESTO!$N$10:$N$262,MATCH($A39,PRESUPUESTO!$A$10:$A$262,0)),""))} | C39: {=IFERROR(INDEX(PRESUPUESTO!$B$10:$B$204,MATCH($A39&"|"&$B39,PRESUPUESTO!$O$10:$O$204,0)),"⚠ no existe en ese módulo")} | I39: =SUMIFS($I$10:$I$31,$A$10:$A$31,$A39,$B$10:$B$31,$B39) | J39: {=IF($A39="","",IFERROR(INDEX(PRESUPUESTO!$D$10:$D$174,MATCH($A39&"|"&$B39,PRESUPUESTO!$O$10:$O$174,0)),"⚠"))} | K39: {=IF($A39="","",IFERROR(INDEX(PRESUPUESTO!$C$10:$C$174,MATCH($A39&"|"&$B39,PRESUPUESTO!$O$10:$O$174,0)),""))} | L39: {=IF($A39="","",IFERROR(INDEX(PRESUPUESTO!$B$10:$B$174,MATCH($A39,PRESUPUESTO!$A$10:$A$174,0)),"⚠ clave no existe"))} | M39: {=IF($A39="","",IFERROR(INDEX(PRESUPUESTO!$C$10:$C$262,MATCH($A39,PRESUPUESTO!$A$10:$A$262,0)),""))} | N39: =IF($A39="","",IFERROR(SUMIF($A$10:$A$509,$A39,$I$10:$I$509)-$M39,""))
A40: ALB08226 | B40: {=IF($A40="","",IFERROR(INDEX(PRESUPUESTO!$N$10:$N$262,MATCH($A40,PRESUPUESTO!$A$10:$A$262,0)),""))} | C40: {=IFERROR(INDEX(PRESUPUESTO!$B$10:$B$204,MATCH($A40&"|"&$B40,PRESUPUESTO!$O$10:$O$204,0)),"⚠ no existe en ese módulo")} | I40: =SUMIFS($I$10:$I$31,$A$10:$A$31,$A40,$B$10:$B$31,$B40) | J40: {=IF($A40="","",IFERROR(INDEX(PRESUPUESTO!$D$10:$D$174,MATCH($A40&"|"&$B40,PRESUPUESTO!$O$10:$O$174,0)),"⚠"))} | K40: {=IF($A40="","",IFERROR(INDEX(PRESUPUESTO!$C$10:$C$174,MATCH($A40&"|"&$B40,PRESUPUESTO!$O$10:$O$174,0)),""))} | L40: {=IF($A40="","",IFERROR(INDEX(PRESUPUESTO!$B$10:$B$174,MATCH($A40,PRESUPUESTO!$A$10:$A$174,0)),"⚠ clave no existe"))} | M40: {=IF($A40="","",IFERROR(INDEX(PRESUPUESTO!$C$10:$C$262,MATCH($A40,PRESUPUESTO!$A$10:$A$262,0)),""))} | N40: =IF($A40="","",IFERROR(SUMIF($A$10:$A$509,$A40,$I$10:$I$509)-$M40,""))
A41: CIM04002 | B41: {=IF($A41="","",IFERROR(INDEX(PRESUPUESTO!$N$10:$N$262,MATCH($A41,PRESUPUESTO!$A$10:$A$262,0)),""))} | C41: {=IFERROR(INDEX(PRESUPUESTO!$B$10:$B$204,MATCH($A41&"|"&$B41,PRESUPUESTO!$O$10:$O$204,0)),"⚠ no existe en ese módulo")} | I41: =SUMIFS($I$10:$I$31,$A$10:$A$31,$A41,$B$10:$B$31,$B41) | J41: {=IF($A41="","",IFERROR(INDEX(PRESUPUESTO!$D$10:$D$174,MATCH($A41&"|"&$B41,PRESUPUESTO!$O$10:$O$174,0)),"⚠"))} | K41: {=IF($A41="","",IFERROR(INDEX(PRESUPUESTO!$C$10:$C$174,MATCH($A41&"|"&$B41,PRESUPUESTO!$O$10:$O$174,0)),""))} | L41: {=IF($A41="","",IFERROR(INDEX(PRESUPUESTO!$B$10:$B$174,MATCH($A41,PRESUPUESTO!$A$10:$A$174,0)),"⚠ clave no existe"))} | M41: {=IF($A41="","",IFERROR(INDEX(PRESUPUESTO!$C$10:$C$262,MATCH($A41,PRESUPUESTO!$A$10:$A$262,0)),""))} | N41: =IF($A41="","",IFERROR(SUMIF($A$10:$A$509,$A41,$I$10:$I$509)-$M41,""))
A42: CIM04003 | B42: {=IF($A42="","",IFERROR(INDEX(PRESUPUESTO!$N$10:$N$262,MATCH($A42,PRESUPUESTO!$A$10:$A$262,0)),""))} | C42: {=IFERROR(INDEX(PRESUPUESTO!$B$10:$B$204,MATCH($A42&"|"&$B42,PRESUPUESTO!$O$10:$O$204,0)),"⚠ no existe en ese módulo")} | I42: =SUMIFS($I$10:$I$31,$A$10:$A$31,$A42,$B$10:$B$31,$B42) | J42: {=IF($A42="","",IFERROR(INDEX(PRESUPUESTO!$D$10:$D$174,MATCH($A42&"|"&$B42,PRESUPUESTO!$O$10:$O$174,0)),"⚠"))} | K42: {=IF($A42="","",IFERROR(INDEX(PRESUPUESTO!$C$10:$C$174,MATCH($A42&"|"&$B42,PRESUPUESTO!$O$10:$O$174,0)),""))} | L42: {=IF($A42="","",IFERROR(INDEX(PRESUPUESTO!$B$10:$B$174,MATCH($A42,PRESUPUESTO!$A$10:$A$174,0)),"⚠ clave no existe"))} | M42: {=IF($A42="","",IFERROR(INDEX(PRESUPUESTO!$C$10:$C$262,MATCH($A42,PRESUPUESTO!$A$10:$A$262,0)),""))} | N42: =IF($A42="","",IFERROR(SUMIF($A$10:$A$509,$A42,$I$10:$I$509)-$M42,""))
A43: CIM04004 | B43: {=IF($A43="","",IFERROR(INDEX(PRESUPUESTO!$N$10:$N$262,MATCH($A43,PRESUPUESTO!$A$10:$A$262,0)),""))} | C43: {=IFERROR(INDEX(PRESUPUESTO!$B$10:$B$204,MATCH($A43&"|"&$B43,PRESUPUESTO!$O$10:$O$204,0)),"⚠ no existe en ese módulo")} | I43: =SUMIFS($I$10:$I$31,$A$10:$A$31,$A43,$B$10:$B$31,$B43) | J43: {=IF($A43="","",IFERROR(INDEX(PRESUPUESTO!$D$10:$D$174,MATCH($A43&"|"&$B43,PRESUPUESTO!$O$10:$O$174,0)),"⚠"))} | K43: {=IF($A43="","",IFERROR(INDEX(PRESUPUESTO!$C$10:$C$174,MATCH($A43&"|"&$B43,PRESUPUESTO!$O$10:$O$174,0)),""))} | L43: {=IF($A43="","",IFERROR(INDEX(PRESUPUESTO!$B$10:$B$174,MATCH($A43,PRESUPUESTO!$A$10:$A$174,0)),"⚠ clave no existe"))} | M43: {=IF($A43="","",IFERROR(INDEX(PRESUPUESTO!$C$10:$C$262,MATCH($A43,PRESUPUESTO!$A$10:$A$262,0)),""))} | N43: =IF($A43="","",IFERROR(SUMIF($A$10:$A$509,$A43,$I$10:$I$509)-$M43,""))
A44: DEM5029 | B44: {=IF($A44="","",IFERROR(INDEX(PRESUPUESTO!$N$10:$N$262,MATCH($A44,PRESUPUESTO!$A$10:$A$262,0)),""))} | C44: {=IFERROR(INDEX(PRESUPUESTO!$B$10:$B$204,MATCH($A44&"|"&$B44,PRESUPUESTO!$O$10:$O$204,0)),"⚠ no existe en ese módulo")} | I44: =SUMIFS($I$10:$I$31,$A$10:$A$31,$A44,$B$10:$B$31,$B44) | J44: {=IF($A44="","",IFERROR(INDEX(PRESUPUESTO!$D$10:$D$174,MATCH($A44&"|"&$B44,PRESUPUESTO!$O$10:$O$174,0)),"⚠"))} | K44: {=IF($A44="","",IFERROR(INDEX(PRESUPUESTO!$C$10:$C$174,MATCH($A44&"|"&$B44,PRESUPUESTO!$O$10:$O$174,0)),""))} | L44: {=IF($A44="","",IFERROR(INDEX(PRESUPUESTO!$B$10:$B$174,MATCH($A44,PRESUPUESTO!$A$10:$A$174,0)),"⚠ clave no existe"))} | M44: {=IF($A44="","",IFERROR(INDEX(PRESUPUESTO!$C$10:$C$262,MATCH($A44,PRESUPUESTO!$A$10:$A$262,0)),""))} | N44: =IF($A44="","",IFERROR(SUMIF($A$10:$A$509,$A44,$I$10:$I$509)-$M44,""))
A45: DEM5030 | B45: {=IF($A45="","",IFERROR(INDEX(PRESUPUESTO!$N$10:$N$262,MATCH($A45,PRESUPUESTO!$A$10:$A$262,0)),""))} | C45: {=IFERROR(INDEX(PRESUPUESTO!$B$10:$B$204,MATCH($A45&"|"&$B45,PRESUPUESTO!$O$10:$O$204,0)),"⚠ no existe en ese módulo")} | I45: =SUMIFS($I$10:$I$31,$A$10:$A$31,$A45,$B$10:$B$31,$B45) | J45: {=IF($A45="","",IFERROR(INDEX(PRESUPUESTO!$D$10:$D$174,MATCH($A45&"|"&$B45,PRESUPUESTO!$O$10:$O$174,0)),"⚠"))} | K45: {=IF($A45="","",IFERROR(INDEX(PRESUPUESTO!$C$10:$C$174,MATCH($A45&"|"&$B45,PRESUPUESTO!$O$10:$O$174,0)),""))} | L45: {=IF($A45="","",IFERROR(INDEX(PRESUPUESTO!$B$10:$B$174,MATCH($A45,PRESUPUESTO!$A$10:$A$174,0)),"⚠ clave no existe"))} | M45: {=IF($A45="","",IFERROR(INDEX(PRESUPUESTO!$C$10:$C$262,MATCH($A45,PRESUPUESTO!$A$10:$A$262,0)),""))} | N45: =IF($A45="","",IFERROR(SUMIF($A$10:$A$509,$A45,$I$10:$I$509)-$M45,""))
A46: DEM5031 | B46: {=IF($A46="","",IFERROR(INDEX(PRESUPUESTO!$N$10:$N$262,MATCH($A46,PRESUPUESTO!$A$10:$A$262,0)),""))} | C46: {=IFERROR(INDEX(PRESUPUESTO!$B$10:$B$204,MATCH($A46&"|"&$B46,PRESUPUESTO!$O$10:$O$204,0)),"⚠ no existe en ese módulo")} | I46: =SUMIFS($I$10:$I$31,$A$10:$A$31,$A46,$B$10:$B$31,$B46) | J46: {=IF($A46="","",IFERROR(INDEX(PRESUPUESTO!$D$10:$D$174,MATCH($A46&"|"&$B46,PRESUPUESTO!$O$10:$O$174,0)),"⚠"))} | K46: {=IF($A46="","",IFERROR(INDEX(PRESUPUESTO!$C$10:$C$174,MATCH($A46&"|"&$B46,PRESUPUESTO!$O$10:$O$174,0)),""))} | L46: {=IF($A46="","",IFERROR(INDEX(PRESUPUESTO!$B$10:$B$174,MATCH($A46,PRESUPUESTO!$A$10:$A$174,0)),"⚠ clave no existe"))} | M46: {=IF($A46="","",IFERROR(INDEX(PRESUPUESTO!$C$10:$C$262,MATCH($A46,PRESUPUESTO!$A$10:$A$262,0)),""))} | N46: =IF($A46="","",IFERROR(SUMIF($A$10:$A$509,$A46,$I$10:$I$509)-$M46,""))
... A49: PRE02226 | B49: {=IF($A49="","",IFERROR(INDEX(PRESUPUESTO!$N$10:$N$262,MATCH($A49,PRESUPUESTO!$A$10:$A$262,0)),""))} | C49: {=IFERROR(INDEX(PRESUPUESTO!$B$10:$B$204,MATCH($A49&"|"&$B49,PRESUPUESTO!$O$10:$O$204,0)),"⚠ no existe en ese módulo")} | I49: =SUMIFS($I$10:$I$31,$A$10:$A$31,$A49,$B$10:$B$31,$B49) | J49: {=IF($A49="","",IFERROR(INDEX(PRESUPUESTO!$D$10:$D$174,MATCH($A49&"|"&$B49,PRESUPUESTO!$O$10:$O$174,0)),"⚠"))} | K49: {=IF($A49="","",IFERROR(INDEX(PRESUPUESTO!$C$10:$C$174,MATCH($A49&"|"&$B49,PRESUPUESTO!$O$10:$O$174,0)),""))} | L49: {=IF($A49="","",IFERROR(INDEX(PRESUPUESTO!$B$10:$B$174,MATCH($A49,PRESUPUESTO!$A$10:$A$174,0)),"⚠ clave no existe"))} | M49: {=IF($A49="","",IFERROR(INDEX(PRESUPUESTO!$C$10:$C$262,MATCH($A49,PRESUPUESTO!$A$10:$A$262,0)),""))} | N49: =IF($A49="","",IFERROR(SUMIF($A$10:$A$509,$A49,$I$10:$I$509)-$M49,""))
B50: {=IF($A50="","",IFERROR(INDEX(PRESUPUESTO!$N$10:$N$262,MATCH($A50,PRESUPUESTO!$A$10:$A$262,0)),""))} | J50: {=IF($A50="","",IFERROR(INDEX(PRESUPUESTO!$D$10:$D$174,MATCH($A50&"|"&$B50,PRESUPUESTO!$O$10:$O$174,0)),"⚠"))} | K50: {=IF($A50="","",IFERROR(INDEX(PRESUPUESTO!$C$10:$C$174,MATCH($A50&"|"&$B50,PRESUPUESTO!$O$10:$O$174,0)),""))} | L50: {=IF($A50="","",IFERROR(INDEX(PRESUPUESTO!$B$10:$B$174,MATCH($A50,PRESUPUESTO!$A$10:$A$174,0)),"⚠ clave no existe"))} | M50: {=IF($A50="","",IFERROR(INDEX(PRESUPUESTO!$C$10:$C$262,MATCH($A50,PRESUPUESTO!$A$10:$A$262,0)),""))} | N50: =IF($A50="","",IFERROR(SUMIF($A$10:$A$509,$A50,$I$10:$I$509)-$M50,""))
B51: {=IF($A51="","",IFERROR(INDEX(PRESUPUESTO!$N$10:$N$262,MATCH($A51,PRESUPUESTO!$A$10:$A$262,0)),""))} | C51: Renglón en rojo = el volumen del generador NO coincide con la cantidad capturada en el presupuesto. | J51: {=IF($A51="","",IFERROR(INDEX(PRESUPUESTO!$D$10:$D$174,MATCH($A51&"|"&$B51,PRESUPUESTO!$O$10:$O$174,0)),"⚠"))} | K51: {=IF($A51="","",IFERROR(INDEX(PRESUPUESTO!$C$10:$C$174,MATCH($A51&"|"&$B51,PRESUPUESTO!$O$10:$O$174,0)),""))} | L51: {=IF($A51="","",IFERROR(INDEX(PRESUPUESTO!$B$10:$B$174,MATCH($A51,PRESUPUESTO!$A$10:$A$174,0)),"⚠ clave no existe"))} | M51: {=IF($A51="","",IFERROR(INDEX(PRESUPUESTO!$C$10:$C$262,MATCH($A51,PRESUPUESTO!$A$10:$A$262,0)),""))} | N51: =IF($A51="","",IFERROR(SUMIF($A$10:$A$509,$A51,$I$10:$I$509)-$M51,""))
B52: {=IF($A52="","",IFERROR(INDEX(PRESUPUESTO!$N$10:$N$262,MATCH($A52,PRESUPUESTO!$A$10:$A$262,0)),""))} | C52: Celda amarilla en FUENTE = el dato viene de un supuesto, no de plano. Hay que confirmarlo antes de cotizar. | J52: {=IF($A52="","",IFERROR(INDEX(PRESUPUESTO!$D$10:$D$174,MATCH($A52&"|"&$B52,PRESUPUESTO!$O$10:$O$174,0)),"⚠"))} | K52: {=IF($A52="","",IFERROR(INDEX(PRESUPUESTO!$C$10:$C$174,MATCH($A52&"|"&$B52,PRESUPUESTO!$O$10:$O$174,0)),""))} | L52: {=IF($A52="","",IFERROR(INDEX(PRESUPUESTO!$B$10:$B$174,MATCH($A52,PRESUPUESTO!$A$10:$A$174,0)),"⚠ clave no existe"))} | M52: {=IF($A52="","",IFERROR(INDEX(PRESUPUESTO!$C$10:$C$262,MATCH($A52,PRESUPUESTO!$A$10:$A$262,0)),""))} | N52: =IF($A52="","",IFERROR(SUMIF($A$10:$A$509,$A52,$I$10:$I$509)-$M52,""))
...

Sheet COMPARATIVO V10
A1: REVISIÓN MANUAL DE REDACCIÓN · V10 vs V11 ACTUALIZADO
A2: NADA DE ESTO SE MODIFICÓ. Compara, decide, y escribe tu decisión en la última columna.
A3: Verificación: el V11 ACTUALIZADO conserva íntegras las 157 redacciones de tu V11 REAL. 0 cambios.
A5: CLAVE | B5: MÓD | C5: SIMILITUD | D5: FILA V11 | E5: REDACCIÓN V10 | F5: REDACCIÓN V11 ACTUAL | G5: NOTA QUE TENÍAS EN V10 | H5: TU DECISIÓN
A6: CIM04005 | B6: M2 | C6: 0.44150943 | D6: 53 | E6: SUMINISTRO Y APLICACIÓN DE IMPERMEABILIZANTE EN MUROS COLINDANTES A BASE DE EMULSIÓN ASFÁLTICA FIBRATADA APLICADA CON CEPILLO EN DOS CAPAS EN MUROS COLINDANTES EXISTENTES PREVIOS AL SANGRADO DE HUMEDADES. INCLUYE MATERIAL, HERRAMIENTA MENOR, MANO DE OBRA Y EQUIPO DE PROTECCIÓN PERSONAL. | F6: SUMINISTRO Y APLICACIÓN DE IMPERMEABILIZANTE EN MUROS COLINDANTES EXISTENTES A BASE DE EMULSIÓN ASFÁLTICA FIBRATADA APLICADA FIBRATADA CON CEPILLO EN DOS CAPAS. INCLUYE MATERIAL, HERRAMIENTA MENOR, MANO DE OBRA Y EQUIPO DE PROTECCIÓN PERSONAL. | G6: SE CORRIJE S EQUITA EL CARTON, Y SE BAJA EL P[RECIO, HABRA QUE EXPLICAR POR QUE ESE DISPARO DEL PRECIO SI LO TENIA,MOS DIFERENTE EN EL ULTIMO PRESUPUESTO
A7: ELE12101 | B7: M2 | C7: 0.45372051 | D7: 68 | E7: OPCIÓN B · PREPARACIÓN VERTICAL ELÉCTRICA PARA NIVEL FUTURO: TUBERÍA CONDUIT AHOGADA CON GUÍA DE NYLON Y REGISTRO DE PASO, DEJANDO PUNTA IDENTIFICADA SOBRE EL NIVEL DE LOSA. INCLUYE MATERIAL, HERRAMIENTA MENOR, MANO DE OBRA Y EQUIPO DE PROTECCIÓN PERSONAL. · CLAVE PROVISIONAL — la definitiva la genera bulk-import.mjs al cargar el concepto al catálogo global. | F7: SALIDA ELÉCTRICA PARA CONTACTOS CON TUBERÍA DE POLIFLEX DE 3/4", CABLEADO DEL #10 Y #12, CHALUPA Y CONEXIÓN. INCLUYE MATERIAL, HERRAMIENTA MENOR, MANO DE OBRA Y EQUIPO DE PROTECCIÓN PERSONAL.
A8: ALB08236 | B8: M6 | C8: 0.53621347 | D8: 216 | E8: OPCIÓN B · ARRANQUES DE COLUMNA PARA NIVEL FUTURO: BASTONES DE VARILLA SALIENTES EN CADA COLUMNA A LA LONGITUD DE TRASLAPE DE TABLA, DOBLADOS Y PROTEGIDOS CON LECHADA DE CEMENTO Y FUNDA DE POLIETILENO. INCLUYE HABILITADO, COLOCACIÓN, PROTECCIÓN, HERRAMIENTA MENOR, MANO DE OBRA Y EQUIPO DE PROTECCIÓN PERSONAL. · La estructura está calculada para 3 niveles: el crecimiento NO requiere recálculo. CLAVE PROVISIONAL — la definitiva la genera bulk-import.mjs al cargar el concepto al catálogo global. | F8: OPCIÓN B · ARRANQUES DE COLUMNA Y ESPERAS DE CASTILLO PARA NIVEL FUTURO: BASTONES DE VARILLA SALIENTES A LA LONGITUD DE TRASLAPE DE TABLA, DOBLADOS Y PROTEGIDOS CON LECHADA DE CEMENTO Y FUNDA DE POLIETILENO. INCLUYE MATERIAL, HERRAMIENTA MENOR, MANO DE OBRA Y EQUIPO DE PROTECCIÓN PERSONAL.
A9: ALB08211 | B9: M2 | C9: 0.55291577 | D9: 57 | E9: FIRME DE CONCRETO CON ACABADO ESCOBILLADO Y CON PENDIENTE PARA DESAGUE PLUVIAL DE 0.10 M DE ESPESOR F'C=150 KG/CM², AGREGADO MÁXIMO DE 3/4", CON MALLA ELECTROSOLDADA. INCLUYE CIMBRADO, MATERIAL, REGLEADO, CURADO, HERRAMIENTA MENOR, MANO DE OBRA Y EQUIPO DE PROTECCIÓN PERSONAL. | F9: ACABADO CEPILLADO EN ÁREA DE PATIO DE SERVICIO (ZONA DE BOILER), CON PENDIENTE HACIA LA BAJADA PLUVIAL. INCLUYE MATERIAL, HERRAMIENTA MENOR, MANO DE OBRA Y EQUIPO DE PROTECCIÓN PERSONAL. | G9: ESTE CONCEPTO ES CON OTRA INTENCION SE MODIFICA POR QUE HAUY PARTES DE LA CASA COMO EL PEQUENO PATIO DONDE IRA EL BOILER PARA DAR PENDIENTE A LA BAJADA PLUVIAL, REVISAR EN PLANO SANITARIO REV 3
A10: ALB08219 | B10: M2 | C10: 0.5648855 | D10: 66 | E10: MURO DE BLOCK ESTRUCTURAL DE CONCRETO ASENTADO CON MORTERO 1:2:7 A PLOMO Y NIVEL, CON REFUERZO DE MALLA DE GALLINERO Y MEZCLA RECORTADA POR AMBAS CARAS. INCLUYE MATERIAL, REFUERZO, HERRAMIENTA MENOR, MANO DE OBRA Y EQUIPO DE PROTECCIÓN PERSONAL. | F10: MURO DE BLOCK ESTRUCTURAL DE CONCRETO ASENTADO CON MORTERO A PLOMO Y NIVEL, CON REFUERZO DE MALLA DE GALLINERO POR AMBAS CARAS. INCLUYE MATERIAL, REFUERZO Y HERRAMIENTA MENOR. NO INCLUYE APLANADO. INCLUYE MATERIAL, HERRAMIENTA MENOR, MANO DE OBRA Y EQUIPO DE PROTECCIÓN PERSONAL.
A11: CIM04004 | B11: M2 | C11: 0.64947245 | D11: 52 | E11: CIMENTACION CON LOSA DE 15 CM DE ESPESOR CON PARRILLA DE ACERO EN AMBOS LECHOS, MALLA ELECTROSOLDADA 6X6 4X4 Y BASTONES DE 3/8" @ 20 CM SEGÚN DESPIECE DEL PLANO ESTRUCTURAL, CT-1 CONTRATRABE CENTRAL Y PERIMETRAL DE 20X40 CM, CON CONCRETO F'C=250 KG/CM². INCLUYE HABILITADO Y ARMADO, SILLETAS, CIMBRA PERIMETRAL Y DES CIMBRADO, COLADO, REGLEADO, CURADO, HERRAMIENTA MENOR, MANO DE OBRA Y EQUIPO DE PROTECCIÓN PERSONAL. | F11: LOSA DE CIMENTACIÓN CON CONTRATRABES INTEGRADAS: LOSA DE 15 CM DE ESPESOR CON PARRILLA EN AMBOS LECHOS, MALLA ELECTROSOLDADA 6-6/4-4 Y BASTONES DE 3/8" A CADA 20 CM; CONTRATRABE CENTRAL Y PERIMETRAL DE 20 X 40 CM, TODO CON CONCRETO F'C=250 KG/CM². INCLUYE HABILITADO Y ARMADO DE ACERO, SILLETAS, CIMBRA, DESCIMBRADO, COLADO, REGLEADO, VIBRADO Y CURADO. INCLUYE MATERIAL, HERRAMIENTA MENOR, MANO DE OBRA Y EQUIPO DE PROTECCIÓN PERSONAL. | G11: TODAS LAS NOTAS QUE AGREGASTE A CADA CONCEPTO DEBERAN IR AQUI EN ESTA COLIUMNA, FORMATO CONDICIONAL AQUI NO FUNCIONA
A12: ARR06009 | B12: M1 | C12: 0.6519945 | D12: 41 | E12: VIAJE DE ESCOMBRO A TIRO AUTORIZADO: RETIRO DEL ESCOMBRO EN CAMIÓN DE VOLTEO CON CAPACIDAD DE TOLVA DE 6 M³, HASTA TIRO AUTORIZADO, CON DISPOSICIÓN LEGAL DEL RESIDUO. INCLUYE RENTA DEL CAMIÓN, COMBUSTIBLE, OPERADOR Y DERECHO DE DESCARGA. · No incluye la carga al camión, que está considerada en el concepto de acarreo. Los viajes se estiman con base en el volumen de escombro calculado; en caso de generarse excedentes, se reportarán y facturarán conforme a los viajes realmente ejecutados. | F12: VIAJE DE ESCOMBRO A TIRO AUTORIZADO: RETIRO DEL ESCOMBRO EN CAMIÓN DE VOLTEO CON CAPACIDAD DE TOLVA DE 6 M³, HASTA TIRO AUTORIZADO, CON DISPOSICIÓN LEGAL DEL RESIDUO. INCLUYE RENTA DEL CAMIÓN, COMBUSTIBLE, OPERADOR Y DERECHO DE DESCARGA.
A13: PRE02226 | B13: M2 | C13: 0.65437788 | D13: 50 | E13: SUMINISTRO Y COLOCACIÓN DE CAPA DE POLIETILENO NEGRO CALIBRE 600 A MANERA DE PLANTILLA ENTRE EL TERRENO MEJORADO Y LA LOSA DE CIMENTACIÓN NUEVA, PARA RECIBIR LA PARRILLA Y EL CONCRETO POSTERIOR. INCLUYE MATERIAL, TRASLAPES, HERRAMIENTA MENOR, MANO DE OBRA Y EQUIPO DE PROTECCIÓN PERSONAL. | F13: SUMINISTRO Y COLOCACIÓN DE CAPA DE POLIETILENO NEGRO CALIBRE 600 A MANERA DE PLANTILLA ENTRE EL TERRENO MEJORADO Y LA LOSA DE CIMENTACIÓN NUEVA PARA RECIBIR LA PARRILLA Y EL CONCRETO POSTERIOR, INCLUYE EL FORRADO DE LOS TRES MUROS COLINDANTES HASTA 1.20 M SOBRE EL NIVEL DEL MURO. INCLUYE MATERIAL, HERRAMIENTA MENOR, MANO DE OBRA Y EQUIPO DE PROTECCIÓN PERSONAL. | G13: pu corregido 25 sin utilidad, se considera forrar hasta peralre de plantilla mas 1.20 sobre muro colondante que son tres los dos laterales y el colundante trasero
A14: HRR10003 | B14: M6 | C14: 0.65994236 | D14: 220 | E14: OPCIÓN B · CUBIERTA LIGERA PROVISIONAL DE CUBO DE ESCALERA A BASE DE ESTRUCTURA METÁLICA Y LÁMINA, CON PENDIENTE Y GOTEO. INCLUYE HABILITADO, SOLDADURA, ANCLAJES, LÁMINA, SELLADO, HERRAMIENTA, MANO DE OBRA Y EQUIPO DE PROTECCIÓN PERSONAL. · Superficie pendiente de la lámina AZ2 del arquitectónico REV.03. CLAVE PROVISIONAL — la definitiva la genera bulk-import.mjs al cargar el concepto al catálogo global. | F14: OPCIÓN B · CUBIERTA LIGERA PROVISIONAL DE CUBO DE ESCALERA Y DE CUBO DE LAVANDERÍA A BASE DE ESTRUCTURA METÁLICA Y LÁMINA, CON PENDIENTE Y GOTEO. INCLUYE HABILITADO, SOLDADURA, ANCLAJES, LÁMINA Y SELLADO. INCLUYE MATERIAL, HERRAMIENTA MENOR, MANO DE OBRA Y EQUIPO DE PROTECCIÓN PERSONAL.
A15: ARR06014 | B15: M4 | C15: 0.66774194 | D15: 204 | E15: ACARREO VERTICAL DE MATERIAL A NIVEL SUPERIOR: ELEVACIÓN MANUAL DE MATERIAL A PIE DE OBRA DESDE PLANTA BAJA HASTA EL NIVEL DE TRABAJO. INCLUYE HERRAMIENTA MENOR, ANDAMIO, MANO DE OBRA Y EQUIPO DE PROTECCIÓN PERSONAL. · Este concepto es el que hace que un nivel NO sea idéntico a otro. CLAVE PROVISIONAL — la definitiva la genera bulk-import.mjs al cargar el concepto al catálogo global. | F15: ACARREO VERTICAL DE MATERIAL A NIVEL SUPERIOR: ELEVACIÓN MANUAL DE MATERIAL A PIE DE OBRA DESDE PLANTA BAJA HASTA EL NIVEL DE TRABAJO. INCLUYE ANDAMIO. INCLUYE MATERIAL, HERRAMIENTA MENOR, MANO DE OBRA Y EQUIPO DE PROTECCIÓN PERSONAL. | G15: ESTO DEBERIA AUIDAR A SER REFUERZO PARA CADA CONCEPTO A PARTIR DE 3 METROS DE ALTURA.
A16: ALB08224 | B16: M3 | C16: 0.67332382 | D16: 128 | E16: LOSA DE ENTREPISO DE VIGUETA Y BOVEDILLA C/A DE 25 CM DE PERALTE, CON CAPA DE COMPRESIÓN DE 5 CM, MALLA ELECTROSOLDADA 6-6/8-8 Y CONCRETO F'C=250 KG/CM². INCLUYE VIGUETA ARMADA, BOVEDILLA, APUNTALAMIENTO, CIMBRA DE ORILLA, DES CIMBRADO, ACARREO Y ELEVACIÓN DE MATERIAL, COLADO, CURADO, HERRAMIENTA MENOR, MANO DE OBRA Y EQUIPO DE PROTECCIÓN PERSONAL. | F16: LOSA DE ENTREPISO DE VIGUETA Y BOVEDILLA DE 25 CM DE PERALTE, CON CAPA DE COMPRESIÓN DE 5 CM, MALLA ELECTROSOLDADA 6-6/8-8 Y CONCRETO F'C=250 KG/CM². INCLUYE VIGUETA ARMADA, BOVEDILLA, APUNTALAMIENTO, CIMBRA DE ORILLA, ACARREO Y ELEVACIÓN DE MATERIAL, COLADO Y CURADO. INCLUYE MATERIAL, HERRAMIENTA MENOR, MANO DE OBRA Y EQUIPO DE PROTECCIÓN PERSONAL. | G16: CONCEPTO FINAL
A17: ALB08238 | B17: M6 | C17: 0.67524116 | D17: 217 | E17: GÁRGOLA DE DESAGÜE DE LOSA DE AZOTEA CON SALIDA A BAJADA PLUVIAL, INCLUYE FORMACIÓN DE PENDIENTE LOCAL, PIEZA, SELLADO Y REMATE. INCLUYE MATERIAL, HERRAMIENTA MENOR, MANO DE OBRA Y EQUIPO DE PROTECCIÓN PERSONAL. · BAP1 y BAP2 identificadas en la lámina AZ del arquitectónico REV.03. CLAVE PROVISIONAL — la definitiva la genera bulk-import.mjs al cargar el concepto al catálogo global. | F17: SUMINISTRO Y COLOCACIÓN DE GÁRGOLA DE DESAGÜE DE LOSA DE AZOTEA CON SALIDA A BAJADA PLUVIAL. INCLUYE FORMACIÓN DE PENDIENTE LOCAL, PIEZA, SELLADO Y REMATE. INCLUYE MATERIAL, HERRAMIENTA MENOR, MANO DE OBRA Y EQUIPO DE PROTECCIÓN PERSONAL.
A18: ALB08226 | B18: M3 | C18: 0.69090909 | D18: 129 | E18: LOSA MACIZA DE CONCRETO ARMADO DE 10 CM DE ESPESOR F'C=250 KG/CM², EN ZONA DE DESCANSO DE ESCALERA Y ÁREAS PARTICULARES. INCLUYE HABILITADO Y ARMADO DE ACERO, CIMBRA DE FONDO, APUNTALAMIENTO, COLADO, REGLEADO, CURADO, HERRAMIENTA MENOR, MANO DE OBRA Y EQUIPO DE PROTECCIÓN PERSONAL. · ES-07. CLAVE PROVISIONAL — la definitiva la genera bulk-import.mjs al cargar el concepto al catálogo global. | F18: LOSA MACIZA DE CONCRETO ARMADO DE 10 CM DE ESPESOR CON PARRILLA DEL #3 A CADA 25 CM Y CONCRETO F'C=250 KG/CM², EN ZONA DE DESCANSO DE ESCALERA Y BAÑO. INCLUYE HABILITADO Y ARMADO, CIMBRA DE FONDO, APUNTALAMIENTO, COLADO, REGLEADO Y CURADO. INCLUYE MATERIAL, HERRAMIENTA MENOR, MANO DE OBRA Y EQUIPO DE PROTECCIÓN PERSONAL. | G18: CONCEPTO FINAL
A19: ALB08218 | B19: M2 | C19: 0.69846678 | D19: 65 | E19: MC-2 MURO DE CONCRETO ARMADO COLADO EN SITIO DE 15 CM DE ESPESOR, ARMADO SEGÚN DESPIECE DEL PLANO ESTRUCTURAL, CON CONCRETO F'C=250 KG/CM². INCLUYE HABILITADO Y ARMADO DE ACERO, CIMBRA A DOS CARAS, COLADO, VIBRADO, CURADO, HERRAMIENTA MENOR, MANO DE OBRA Y EQUIPO DE PROTECCIÓN PERSONAL. | F19: MC-2 MURO DE CONCRETO ARMADO DOBLE DE 1.30 X 0.20 M CON DOS COLUMNAS TIPO C Y ACERO DE REFUERZO DE 3/8", CON CONCRETO F'C=250 KG/CM². INCLUYE HABILITADO Y ARMADO DE ACERO, CIMBRA A DOS CARAS, COLADO, VIBRADO Y CURADO. INCLUYE MATERIAL, HERRAMIENTA MENOR, MANO DE OBRA Y EQUIPO DE PROTECCIÓN PERSONAL. | G19: FORMATO CONDICIONAL NO SE POR QUE SE VE TODO ROSA, REVISAR EN TODOS QUE YA ESTAN COMPLETOS POR QUE SE VE ROSA
A20: HRR10001 | B20: M6 | C20: 0.69852105 | D20: 219 | E20: OPCIÓN B · ESTRUCTURA METÁLICA PROVISIONAL PARA BASE DE TINACO SOBRE CUBO DE ESCALERA: BASTIDOR DE PERFIL TUBULAR ESTRUCTURAL CON PLACAS DE APOYO ANCLADAS A LA LOSA, ALTURA DE PROYECTO, CON ACABADO ANTICORROSIVO. INCLUYE HABILITADO, SOLDADURA, ANCLAJES, ELEVACIÓN, MONTAJE, PINTURA, HERRAMIENTA, MANO DE OBRA Y EQUIPO DE PROTECCIÓN PERSONAL. · Desmontable y reutilizable cuando se construya el nivel futuro. CLAVE PROVISIONAL — la definitiva la genera bulk-import.mjs al cargar el concepto al catálogo global. | F20: OPCIÓN B · ESTRUCTURA METÁLICA PROVISIONAL PARA BASE DE TINACO SOBRE CUBO DE ESCALERA Y SOBRE CUBO DE LAVANDERÍA: BASTIDOR DE PERFIL TUBULAR ESTRUCTURAL CON PLACAS DE APOYO ANCLADAS A LA LOSA Y ACABADO ANTICORROSIVO. INCLUYE HABILITADO, SOLDADURA, ANCLAJES, ELEVACIÓN, MONTAJE Y PINTURA. INCLUYE MATERIAL, HERRAMIENTA MENOR, MANO DE OBRA Y EQUIPO DE PROTECCIÓN PERSONAL.
A21: ALB08222 | B21: M3 | C21: 0.70671378 | D21: 126 | E21: T-4 DE FACHADA: TRABE DE SECCIÓN 20 X 25 CM ARMADA SEGÚN DESPIECE DEL PLANO ESTRUCTURAL, CON CONCRETO F'C=250 KG/CM². INCLUYE HABILITADO Y ARMADO DE ACERO, CIMBRA Y DESCIMBRA, APUNTALAMIENTO, COLADO, VIBRADO, CURADO, HERRAMIENTA MENOR, MANO DE OBRA Y EQUIPO DE PROTECCIÓN PERSONAL. | F21: TRABE T-4 DE SECCIÓN 20 X 25 CM CON 4 VARILLAS DE 1/2", TRABE DE FACHADA, CON CONCRETO F'C=250 KG/CM². INCLUYE HABILITADO Y ARMADO DE ACERO, CIMBRA Y DESCIMBRA, APUNTALAMIENTO, COLADO, VIBRADO Y CURADO. INCLUYE MATERIAL, HERRAMIENTA MENOR, MANO DE OBRA Y EQUIPO DE PROTECCIÓN PERSONAL. | G21: ESTA ES EL CONCEPTO FINAL PARA ESTA TRABE TIPO
A22: ARR6013 | B22: M1 | C22: 0.75186104 | D22: 40 | E22: ACARREO DEL ESCOMBRO DESDE EL CENTRO DE ACOPIO DENTRO DEL TAPIAL HASTA EL CAMIÓN DE VOLTEO A PIE DE CALLE, EN UN TRAMO APROXIMADO DE 25 METROS LINEALES POR EL PASO DE SERVIDUMBRE, INCLUYENDO LA CARGA MANUAL AL CAMIÓN. INCLUYE CARRETILLAS, HERRAMIENTA MENOR, MANO DE OBRA Y EQUIPO DE PROTECCIÓN PERSONAL. · Volumen suelto, con factor de abundamiento de 1.35 para demolición y 1.25 para material de excavación. El paso de servidumbre de 3.00 m impide el uso de maquinaria, por lo que el acarreo es manual. | F22: ACARREO DEL ESCOMBRO DESDE EL CENTRO DE ACOPIO DENTRO DEL TAPIAL HASTA EL CAMIÓN DE VOLTEO A PIE DE CALLE, EN UN TRAMO APROXIMADO DE 25 METROS LINEALES POR EL PASO DE SERVIDUMBRE, INCLUYENDO LA CARGA MANUAL AL CAMIÓN. INCLUYE CARRETILLAS, HERRAMIENTA MENOR, MANO DE OBRA Y EQUIPO DE PROTECCIÓN PERSONAL.
A23: EXV3019 | B23: M1 | C23: 0.75494071 | D23: 44 | E23: NIVELACIÓN DEL TERRENO CON MEJORAMIENTO A BASE DE TEPETATE COMPACTADO AL 90% PROCTOR, APISONADO CON BAILARINA, HASTA ALCANZAR EL NIVEL DE DESPLANTE DE PROYECTO. INCLUYE EL TALUD EN CARTABÓN DE LAS CONTRATRABES DE CIMENTACIÓN, SUMINISTRO Y TENDIDO DEL TEPETATE, RENTA DE BAILARINA, COMBUSTIBLE, AGUA PARA COMPACTACIÓN, HERRAMIENTA MENOR, MANO DE OBRA Y EQUIPO DE PROTECCIÓN PERSONAL. · Aplica únicamente en la zona del patio exterior (29.26 m²), donde se demolió el concreto pobre. En la zona de la vivienda no aplica: la losa de cimentación nueva se cuela sobre la losa existente con membrana de polietileno cal. 600 de por medio. | F23: NIVELACIÓN DEL TERRENO CON MEJORAMIENTO A BASE DE TEPETATE COMPACTADO AL 90% PROCTOR, APISONADO CON BAILARINA, HASTA ALCANZAR EL NIVEL DE DESPLANTE DE PROYECTO. INCLUYE EL TALUD EN CARTABÓN DE LAS CONTRATRABES DE CIMENTACIÓN, SUMINISTRO Y TENDIDO DEL TEPETATE, RENTA DE BAILARINA, COMBUSTIBLE, AGUA PARA COMPACTACIÓN, HERRAMIENTA MENOR, MANO DE OBRA Y EQUIPO DE PROTECCIÓN PERSONAL.
A24: ALB08223 | B24: M3 | C24: 0.75638051 | D24: 127 | E24: CADENA DE CERRAMIENTO CR DE SECCIÓN 15 X 27 CM ARMADA CON ARMEX, CON CONCRETO F'C=250 KG/CM². INCLUYE HABILITADO, CIMBRA, COLADO, CURADO, HERRAMIENTA MENOR, MANO DE OBRA Y EQUIPO DE PROTECCIÓN PERSONAL. | F24: CADENA DE CERRAMIENTO CR ARMADA CON ARMEX 15 X 25 MÁS 2 VARILLAS DEL #3, CON CONCRETO F'C=250 KG/CM². INCLUYE HABILITADO, CIMBRA, COLADO Y CURADO. INCLUYE MATERIAL, HERRAMIENTA MENOR, MANO DE OBRA Y EQUIPO DE PROTECCIÓN PERSONAL. | G24: ESTA ES EL CONCEPTO FINAL PARA ESTOS CERRAMIENTOS
A25: ALB08234 | B25: M6 | C25: 0.75974026 | D25: 215 | E25: OPCIÓN B · TAPA PROVISIONAL DE HUECO DE ESCALERA: BASTIDOR DE MADERA ANCLADO AL BORDE DE LOSA CON SELLADO PERIMETRAL, RETIRABLE SIN DAÑAR EL ARMADO DE CONTINUIDAD. INCLUYE MATERIAL, HERRAJES, SELLADOR, HERRAMIENTA MENOR, MANO DE OBRA Y EQUIPO DE PROTECCIÓN PERSONAL. · CLAVE PROVISIONAL — la definitiva la genera bulk-import.mjs al cargar el concepto al catálogo global. | F25: OPCIÓN B · TAPA PROVISIONAL DE HUECO DE ESCALERA: BASTIDOR DE MADERA ANCLADO AL BORDE DE LOSA CON SELLADO PERIMETRAL, RETIRABLE SIN DAÑAR EL ARMADO DE CONTINUIDAD. INCLUYE MATERIAL, HERRAMIENTA MENOR, MANO DE OBRA Y EQUIPO DE PROTECCIÓN PERSONAL.
A26: PRE02225 | B26: M1 | C26: 0.76401565 | D26: 14 | E26: MURETE PROVISIONAL DE OBRA: FABRICACIÓN DE MURETE PROVISIONAL DE MADERA (POSTE, TABLA Y CLAVOS) ADOSADO AL TAPIAL, PARA ALOJAR EL INTERRUPTOR TERMOMAGNÉTICO DE OBRA Y EL RACK DE CONTACTOS DE USO RUDO. INCLUYE MATERIAL ELÉCTRICO, HERRAMIENTA MENOR, MANO DE OBRA Y EQUIPO DE PROTECCIÓN PERSONAL. · Se construye inmediatamente después del corte de la acometida eléctrica existente, como parte de la misma maniobra de desmantelamiento. Es la fuente de energía para toda la obra. | F26: MURETE PROVISIONAL DE OBRA: FABRICACIÓN DE MURETE PROVISIONAL DE MADERA (POSTE, TABLA Y CLAVOS) ADOSADO AL TAPIAL, PARA ALOJAR EL INTERRUPTOR TERMOMAGNÉTICO DE OBRA Y EL RACK DE CONTACTOS DE USO RUDO. INCLUYE MATERIAL ELÉCTRICO, HERRAMIENTA MENOR, MANO DE OBRA Y EQUIPO DE PROTECCIÓN PERSONAL.
A27: ALB08221 | B27: M3 | C27: 0.77031802 | D27: 122 | E27: TRABE T-1 DE SECCIÓN 15 X 25 CM ARMADA SEGÚN DESPIECE DEL PLANO ESTRUCTURAL, CON CONCRETO F'C=250 KG/CM². INCLUYE HABILITADO Y ARMADO DE ACERO, CIMBRA Y DESCIMBRA, APUNTALAMIENTO, COLADO, VIBRADO, CURADO, HERRAMIENTA MENOR, MANO DE OBRA Y EQUIPO DE PROTECCIÓN PERSONAL. | F27: TRABE T-1 DE SECCIÓN 15 X 25 CM CON 4 VARILLAS DEL #3 Y ESTRIBOS DEL #2 A CADA 20 CM, CON CONCRETO F'C=250 KG/CM². INCLUYE HABILITADO Y ARMADO DE ACERO, CIMBRA Y DESCIMBRA, APUNTALAMIENTO, COLADO, VIBRADO Y CURADO. INCLUYE MATERIAL, HERRAMIENTA MENOR, MANO DE OBRA Y EQUIPO DE PROTECCIÓN PERSONAL. | G27: ESTA ES EL CONCEPTO FINAL PARA ESTA TRABE TIPO
A28: DEM5028 | B28: M1 | C28: 0.79958463 | D28: 32 | E28: CORTE DE LA LOSA DE PISO FIRME EXISTENTE, CON CORTADORA DE PISO TIPO WALK-BEHIND Y DISCO DE DIAMANTE PARA CONCRETO, SOBRE EL LÍMITE DE COLINDANCIA Y SOBRE EL TRAZO DE LAS TRINCHERAS CT-1 DE LA CIMENTACIÓN NUEVA. INCLUYE RENTA DE EQUIPO, DISCO DE CORTE, FLETE DE MAQUINARIA, HERRAMIENTA MENOR, MANO DE OBRA Y EQUIPO DE PROTECCIÓN PERSONAL CON PROTECCIÓN OCULAR, AUDITIVA Y RESPIRATORIA. · Se ejecuta en la misma vuelta de renta que el corte de azotea. La losa de piso existente se conserva; el corte solo la independiza de los muros compartidos y abre el trazo de las trincheras. | F28: CORTE DE LA LOSA DE PISO FIRME EXISTENTE, CON CORTADORA DE PISO TIPO WALK-BEHIND Y DISCO DE DIAMANTE PARA CONCRETO, SOBRE EL LÍMITE DE COLINDANCIA Y SOBRE EL TRAZO DE LAS TRINCHERAS CT-1 DE LA CIMENTACIÓN NUEVA. INCLUYE RENTA DE EQUIPO, DISCO DE CORTE, FLETE DE MAQUINARIA, HERRAMIENTA MENOR, MANO DE OBRA Y EQUIPO DE PROTECCIÓN PERSONAL CON PROTECCIÓN OCULAR, AUDITIVA Y RESPIRATORIA.
A29: ALB08216 | B29: M2 | C29: 0.80208333 | D29: 62 | E29: K-1 CASTILLO DE SECCIÓN 15 X 20 CM Y UNA ALTURA DE 2.50 M A NIVEL BAJO LECHO DE LOSA DE ENTREPISO ARMADO CON ARMEX 15-20-4, CON CONCRETO F'C=200 KG/CM². INCLUYE HABILITADO, CIMBRA, COLADO, VIBRADO, CURADO, HERRAMIENTA MENOR, MANO DE OBRA Y EQUIPO DE PROTECCIÓN PERSONAL. | F29: K-1 CASTILLO DE SECCIÓN 15 X 20 CM ARMADO CON ARMEX 15-20-4 MÁS 2 VARILLAS DEL #3, ALTURA DE 2.50 M A NIVEL BAJO LECHO DE LOSA DE ENTREPISO, CON CONCRETO F'C=250 KG/CM². INCLUYE HABILITADO, CIMBRA, COLADO, VIBRADO Y CURADO. INCLUYE MATERIAL, HERRAMIENTA MENOR, MANO DE OBRA Y EQUIPO DE PROTECCIÓN PERSONAL.
A30: ALB8209 | B30: M1 | C30: 0.80763984 | D30: 46 | E30: RELLENO COMPACTADO Y FIRME DE CONCRETO SOBRE LA RANURA DE LA LÍNEA SANITARIA NUEVA, PARA RESTITUIR EL PISO AL NIVEL EXISTENTE. INCLUYE RELLENO CON MATERIAL PRODUCTO DE LA EXCAVACIÓN COMPACTADO EN CAPAS, FIRME DE CONCRETO, MATERIAL, HERRAMIENTA MENOR, MANO DE OBRA Y EQUIPO DE PROTECCIÓN PERSONAL. · Se ejecuta después de probada la línea sanitaria nueva. Restituye el piso del paso de servidumbre para no dejar obstrucción a los vecinos. | F30: RELLENO COMPACTADO Y FIRME DE CONCRETO SOBRE LA RANURA DE LA LÍNEA SANITARIA NUEVA, PARA RESTITUIR EL PISO AL NIVEL EXISTENTE. INCLUYE RELLENO CON MATERIAL PRODUCTO DE LA EXCAVACIÓN COMPACTADO EN CAPAS, FIRME DE CONCRETO, MATERIAL, HERRAMIENTA MENOR, MANO DE OBRA Y EQUIPO DE PROTECCIÓN PERSONAL.
A31: ALB08215 | B31: M2 | C31: 0.81024096 | D31: 61 | E31: C-4 COLUMNA DE SECCIÓN 20 X 40 CM Y UNA ALTURA DE 2.50 M A NIVEL BAJO LECHO DE LOSA DE ENTREPISO ARMADA SEGÚN DESPIECE DEL PLANO ESTRUCTURAL, CON CONCRETO F'C=250 KG/CM². INCLUYE HABILITADO Y ARMADO DE ACERO, CIMBRA Y DESCIMBRA, COLADO, VIBRADO, CURADO, ANDAMIO, HERRAMIENTA MENOR, MANO DE OBRA Y EQUIPO DE PROTECCIÓN PERSONAL. | F31: C-4 COLUMNA DE SECCIÓN 20 X 40 CM CON 8 VARILLAS DEL #4 Y ESTRIBOS DEL #3, ALTURA DE 2.50 M A NIVEL BAJO LECHO DE LOSA DE ENTREPISO, CON CONCRETO F'C=250 KG/CM². INCLUYE HABILITADO Y ARMADO DE ACERO, CIMBRA Y DESCIMBRA, COLADO, VIBRADO, CURADO Y ANDAMIO. INCLUYE MATERIAL, HERRAMIENTA MENOR, MANO DE OBRA Y EQUIPO DE PROTECCIÓN PERSONAL. | G31: FORMATO CONDICIONAL NO SE POR QUE SE VE TODO ROSA, REVISAR EN TODOS QUE YA ESTAN COMPLETOS POR QUE SE VE ROSA
A32: HSI14093 | B32: M1 | C32: 0.81538462 | D32: 28 | E32: REUBICACIÓN Y RECONEXIÓN DE TINACOS DE CASA COLINDANTE: REUBICACIÓN Y RECONEXIÓN DE TINACO DE LA CASA COLINDANTE A LA LÍNEA HIDRÁULICA NUEVA. INCLUYE DESMONTAJE, TRASLADO, MONTAJE SOBRE SU BASE, FIJACIÓN CON ABRAZADERAS, CONEXIÓN FINAL A LA LÍNEA NUEVA, HERRAMIENTA MENOR, MANO DE OBRA Y EQUIPO DE PROTECCIÓN PERSONAL. · Precio unitario por lote. Corresponde a los 2 tinacos de la casa colindante inmediata. Los tinacos de los demás departamentos no se reubican. | F32: REUBICACIÓN Y RECONEXIÓN DE TINACOS DE CASA COLINDANTE: REUBICACIÓN Y RECONEXIÓN DE TINACO DE LA CASA COLINDANTE A LA LÍNEA HIDRÁULICA NUEVA. INCLUYE DESMONTAJE, TRASLADO, MONTAJE SOBRE SU BASE, FIJACIÓN CON ABRAZADERAS, CONEXIÓN FINAL A LA LÍNEA NUEVA, HERRAMIENTA MENOR, MANO DE OBRA Y EQUIPO DE PROTECCIÓN PERSONAL.
A33: HSI14095 | B33: M6 | C33: 0.82550336 | D33: 222 | E33: OPCIÓN B · PREPARACIÓN VERTICAL HIDROSANITARIA PARA NIVEL FUTURO: TRAMOS DE TUBERÍA AHOGADOS CON TAPÓN Y GUÍA, DEJANDO PUNTAS IDENTIFICADAS SOBRE EL NIVEL DE LOSA. INCLUYE MATERIAL, HERRAMIENTA MENOR, MANO DE OBRA Y EQUIPO DE PROTECCIÓN PERSONAL. · CLAVE PROVISIONAL — la definitiva la genera bulk-import.mjs al cargar el concepto al catálogo global. | F33: OPCIÓN B · PREPARACIÓN VERTICAL HIDROSANITARIA PARA NIVEL FUTURO: TRAMOS DE TUBERÍA AHOGADOS CON TAPÓN Y GUÍA, DEJANDO PUNTAS IDENTIFICADAS SOBRE EL NIVEL DE LOSA. INCLUYE MATERIAL, HERRAMIENTA MENOR, MANO DE OBRA Y EQUIPO DE PROTECCIÓN PERSONAL.
A34: DEM5030 | B34: M1 | C34: 0.82564679 | D34: 34 | E34: DEMOLICIÓN DE LA LOSA DE AZOTEA O CUBIERTA DE CONCRETO DE LA VIVIENDA, DE 12 CM DE ESPESOR, PREVIAMENTE CORTADA EN SU PERÍMETRO, CON MARTILLO DEMOLEDOR ELÉCTRICO. TRABAJOS A UNA ALTURA A PARTIR DE 3 METROS. INCLUYE LEVANTADO DEL ESCOMBRO Y SU ACOPIO DENTRO DE LA OBRA, RENTA DE EQUIPO, HERRAMIENTA MENOR, MANO DE OBRA, ANDAMIOS, ARNÉS Y EQUIPO DE PROTECCIÓN PERSONAL. · Se demuele de adentro hacia afuera, dejando intactos los muros compartidos. Corresponde a los 50.43 m² de la huella de la vivienda por 12 cm de espesor. | F34: DEMOLICIÓN DE LA LOSA DE AZOTEA O CUBIERTA DE CONCRETO DE LA VIVIENDA, DE 12 CM DE ESPESOR, PREVIAMENTE CORTADA EN SU PERÍMETRO, CON MARTILLO DEMOLEDOR ELÉCTRICO. TRABAJOS A UNA ALTURA A PARTIR DE 3 METROS. INCLUYE LEVANTADO DEL ESCOMBRO Y SU ACOPIO DENTRO DE LA OBRA, RENTA DE EQUIPO, HERRAMIENTA MENOR, MANO DE OBRA, ANDAMIOS, ARNÉS Y EQUIPO DE PROTECCIÓN PERSONAL.
A35: PRE02223 | B35: M1 | C35: 0.82704811 | D35: 12 | E35: TRAZO Y NIVELACIÓN DEL ÁREA A CONSTRUIR: TRAZO Y NIVELACIÓN DE PLATAFORMA SEGÚN LOS NIVELES DE DESPLANTE DEL PROYECTO, SOBRE LA TOTALIDAD DEL PREDIO DE CASA 2 (81.24 M² DE DESPLANTE). INCLUYE HILO, ESTACAS, CRUCETAS DE MADERA, NIVEL, EQUIPO TOPOGRÁFICO, HERRAMIENTA MENOR, MANO DE OBRA Y EQUIPO DE PROTECCIÓN PERSONAL. · Superficie de desplante del proyecto según cuadro de áreas del plano A-01. Se ejecuta después del tapial y antes de la demolición. | F35: TRAZO Y NIVELACIÓN DEL ÁREA A CONSTRUIR: TRAZO Y NIVELACIÓN DE PLATAFORMA SEGÚN LOS NIVELES DE DESPLANTE DEL PROYECTO, SOBRE LA TOTALIDAD DEL PREDIO DE CASA 2 (81.24 M² DE DESPLANTE). INCLUYE HILO, ESTACAS, CRUCETAS DE MADERA, NIVEL, EQUIPO TOPOGRÁFICO, HERRAMIENTA MENOR, MANO DE OBRA Y EQUIPO DE PROTECCIÓN PERSONAL. | G35: no me acuerdo
A36: ALB08213 | B36: M2 | C36: 0.83024691 | D36: 59 | E36: C-2 COLUMNA DE SECCIÓN 15 X 40 CM Y UNA ALTURA DE 2.50 M A NIVEL BAJO LECHO DE LOSA DE ENTREPISO. ARMADA SEGÚN DESPIECE DEL PLANO ESTRUCTURAL, CON CONCRETO F'C=250 KG/CM². INCLUYE HABILITADO Y ARMADO DE ACERO, CIMBRA Y DESCIMBRA, COLADO, VIBRADO, CURADO, ANDAMIO, HERRAMIENTA MENOR, MANO DE OBRA Y EQUIPO DE PROTECCIÓN PERSONAL. | F36: C-2 COLUMNA DE SECCIÓN 15 X 40 CM CON 4 VARILLAS DEL #4 Y ALTURA DE 2.50 M A NIVEL BAJO LECHO DE LOSA DE ENTREPISO, CON CONCRETO F'C=250 KG/CM². INCLUYE HABILITADO Y ARMADO DE ACERO, CIMBRA Y DESCIMBRA, COLADO, VIBRADO, CURADO Y ANDAMIO. INCLUYE MATERIAL, HERRAMIENTA MENOR, MANO DE OBRA Y EQUIPO DE PROTECCIÓN PERSONAL. | G36: FORMATO CONDICIONAL NO SE POR QUE SE VE TODO ROSA, REVISAR EN TODOS QUE YA ESTAN COMPLETOS POR QUE SE VE ROSA
A37: ALB08214 | B37: M2 | C37: 0.83153014 | D37: 60 | E37: C-3 COLUMNA DE SECCIÓN 20 X 20 CM Y UNA ALTURA DE 2.50 M A NIVEL BAJO LECHO DE LOSA DE ENTREPISO ARMADA SEGÚN DESPIECE DEL PLANO ESTRUCTURAL, CON CONCRETO F'C=250 KG/CM². INCLUYE HABILITADO Y ARMADO DE ACERO, CIMBRA Y DESCIMBRA, COLADO, VIBRADO, CURADO, ANDAMIO, HERRAMIENTA MENOR, MANO DE OBRA Y EQUIPO DE PROTECCIÓN PERSONAL. | F37: C-3 COLUMNA DE SECCIÓN 20 X 20 CM CON 4 VARILLAS DEL #4 Y ALTURA DE 2.50 M A NIVEL BAJO LECHO DE LOSA DE ENTREPISO, CON CONCRETO F'C=250 KG/CM². INCLUYE HABILITADO Y ARMADO DE ACERO, CIMBRA Y DESCIMBRA, COLADO, VIBRADO, CURADO Y ANDAMIO. INCLUYE MATERIAL, HERRAMIENTA MENOR, MANO DE OBRA Y EQUIPO DE PROTECCIÓN PERSONAL. | G37: FORMATO CONDICIONAL NO SE POR QUE SE VE TODO ROSA, REVISAR EN TODOS QUE YA ESTAN COMPLETOS POR QUE SE VE ROSA
A38: DEM5033 | B38: M1 | C38: 0.83705542 | D38: 37 | E38: DEMOLICIÓN Y RETIRO DE TINACOS DE FIBROCEMENTO (ASBESTO) EXISTENTES EN LA AZOTEA DE LA VIVIENDA A DEMOLER, CON HUMECTACIÓN PREVIA DE LA PIEZA PARA ABATIR LA EMISIÓN DE FIBRAS, EMBALAJE DEL RESIDUO EN PLÁSTICO DE CALIBRE GRUESO Y DISPOSICIÓN FINAL EN TIRADERO AUTORIZADO PARA RESIDUOS PELIGROSOS. TRABAJOS A UNA ALTURA A PARTIR DE 3 METROS. INCLUYE MATERIAL DE EMBALAJE, TRANSPORTE A TIRADERO AUTORIZADO, HERRAMIENTA MENOR, MANO DE OBRA, ANDAMIOS Y EQUIPO DE PROTECCIÓN PERSONAL CON PROTECCIÓN RESPIRATORIA. · Corresponde a los 2 tinacos de fibrocemento propios de la vivienda a demoler. Trabajo de riesgo especial: el residuo no puede mezclarse con el escombro común ni disponerse en tiradero municipal. | F38: DEMOLICIÓN Y RETIRO DE TINACOS DE FIBROCEMENTO (ASBESTO) EXISTENTES EN LA AZOTEA DE LA VIVIENDA A DEMOLER, CON HUMECTACIÓN PREVIA DE LA PIEZA PARA ABATIR LA EMISIÓN DE FIBRAS, EMBALAJE DEL RESIDUO EN PLÁSTICO DE CALIBRE GRUESO Y DISPOSICIÓN FINAL EN TIRADERO AUTORIZADO PARA RESIDUOS PELIGROSOS. TRABAJOS A UNA ALTURA A PARTIR DE 3 METROS. INCLUYE MATERIAL DE EMBALAJE, TRANSPORTE A TIRADERO AUTORIZADO, HERRAMIENTA MENOR, MANO DE OBRA, ANDAMIOS Y EQUIPO DE PROTECCIÓN PERSONAL CON PROTECCIÓN RESPIRATORIA.
A39: DEM5032 | B39: M1 | C39: 0.84730803 | D39: 36 | E39: RANURA EN EL PISO DE CONCRETO EXISTENTE EN PATIO, DE 40 CM DE ANCHO POR 60 CM DE PROFUNDIDAD, PARA ALOJAR LA LÍNEA SANITARIA NUEVA DE 4" QUE DA SERVICIO A CASA 2 (EL PROYECTO), CASA 3 Y CASA 4 SEGÚN CROQUIS DEL TÍTULO DE PROPIEDAD, FOLIO CATASTRAL CA 17/022. INCLUYE CORTE PREVIO, DEMOLICIÓN CON MARTILLO DEMOLEDOR ELÉCTRICO, LEVANTADO DEL ESCOMBRO PRODUCTO DEL CORTE Y SU ACOPIO DENTRO DE LA OBRA, RENTA DE EQUIPO, HERRAMIENTA MENOR, MANO DE OBRA Y EQUIPO DE PROTECCIÓN PERSONAL. · La línea sanitaria actual pasa por el frente de la vivienda y es compartida con los departamentos del fondo. La ranura aloja el trayecto nuevo que sustituye al existente. | F39: RANURA EN EL PISO DE CONCRETO EXISTENTE EN PATIO, DE 40 CM DE ANCHO POR 60 CM DE PROFUNDIDAD, PARA ALOJAR LA LÍNEA SANITARIA NUEVA DE 4" QUE DA SERVICIO A CASA 2 (EL PROYECTO), CASA 3 Y CASA 4 SEGÚN CROQUIS DEL TÍTULO DE PROPIEDAD, FOLIO CATASTRAL CA 17/022. INCLUYE CORTE PREVIO, DEMOLICIÓN CON MARTILLO DEMOLEDOR ELÉCTRICO, LEVANTADO DEL ESCOMBRO PRODUCTO DEL CORTE Y SU ACOPIO DENTRO DE LA OBRA, RENTA DE EQUIPO, HERRAMIENTA MENOR, MANO DE OBRA Y EQUIPO DE PROTECCIÓN PERSONAL.
A40: HSI14094 | B40: M1 | C40: 0.85109718 | D40: 29 | E40: SUMINISTRO E INSTALACIÓN DE TUBERÍA PVC SANITARIO DE 4" AHOGADA EN RANURA, CON SUS CONEXIONES, PARA LA LÍNEA SANITARIA NUEVA QUE DA SERVICIO A CASA 2 (EL PROYECTO), CASA 3 Y CASA 4 SEGÚN CROQUIS DEL TÍTULO DE PROPIEDAD, FOLIO CATASTRAL CA 17/022, SUSTITUYENDO EL TRAYECTO EXISTENTE QUE PASA POR EL FRENTE DE LA VIVIENDA. INCLUYE TUBERÍA, CODOS, YEES, TEES, PEGAMENTO, NIVELACIÓN DE PENDIENTE, MATERIAL, HERRAMIENTA MENOR, MANO DE OBRA Y EQUIPO DE PROTECCIÓN PERSONAL. REGISTRO SANITARIO DE 40 X 60 X 100 CM: FABRICACIÓN DE REGISTRO SANITARIO DEL PROYECTO. INCLUYE PLANTILLA DE CONCRETO SIMPLE F'C=150 KG/CM² DE 5 CM DE PERALTE, MUROS DE TABIQUE RECOCIDO DE 7 X 14 X 28 CM JUNTEADOS CON MORTERO CEMENTO-ARENA 1:4, APLANADO CON ACABADO PULIDO AL INTERIOR, VÉRTICES RESUELTOS EN CHAFLÁN A 45 GRADOS, ARENERO DE 5 CM BAJO EL LECHO INFERIOR DE LOS TUBOS DE 4" PARA RETENCIÓN DE SEDIMENTOS, TAPA DE REGISTRO DE LA MISMA CALIDAD QUE LA PLANTILLA, EXCAVACIÓN, MATERIAL, HERRAMIENTA MENOR, MANO DE OBRA Y EQUIPO DE PROTECCIÓN PERSONAL. R E S U M E N P O R PA R T I DAS PREPARACIÓN Y PRELIMINARES · Sustituye el trayecto actual que cruza frente a la vivienda. La pendiente se nivela hacia el registro nuevo. El arenero de 5 cm deja los tubos de 4" elevados respecto del fondo de la plantilla, de modo que los sedimentos se depositen en ese espacio y no obstruyan el lecho inferior interior del tubo. Los chaflanes a 45 grados en los vértices evitan la acumulación en esquinas. | F40: SUMINISTRO E INSTALACIÓN DE TUBERÍA PVC SANITARIO DE 4" AHOGADA EN RANURA, CON SUS CONEXIONES, PARA LA LÍNEA SANITARIA NUEVA QUE DA SERVICIO A CASA 2 (EL PROYECTO), CASA 3 Y CASA 4 SEGÚN CROQUIS DEL TÍTULO DE PROPIEDAD, FOLIO CATASTRAL CA 17/022, SUSTITUYENDO EL TRAYECTO EXISTENTE QUE PASA POR EL FRENTE DE LA VIVIENDA. INCLUYE TUBERÍA, CODOS, YEES, TEES, PEGAMENTO, NIVELACIÓN DE PENDIENTE, MATERIAL, HERRAMIENTA MENOR, MANO DE OBRA Y EQUIPO DE PROTECCIÓN PERSONAL. REGISTRO SANITARIO DE 40 X 60 X 100 CM: FABRICACIÓN DE REGISTRO SANITARIO DEL PROYECTO. INCLUYE PLANTILLA DE CONCRETO SIMPLE F'C=150 KG/CM² DE 5 CM DE PERALTE, MUROS DE TABIQUE RECOCIDO DE 7 X 14 X 28 CM JUNTEADOS CON MORTERO CEMENTO-ARENA 1:4, APLANADO CON ACABADO PULIDO AL INTERIOR, VÉRTICES RESUELTOS EN CHAFLÁN A 45 GRADOS, ARENERO DE 5 CM BAJO EL LECHO INFERIOR DE LOS TUBOS DE 4" PARA RETENCIÓN DE SEDIMENTOS, TAPA DE REGISTRO DE LA MISMA CALIDAD QUE LA PLANTILLA, EXCAVACIÓN, MATERIAL, HERRAMIENTA MENOR, MANO DE OBRA Y EQUIPO DE PROTECCIÓN PERSONAL. R E S U M E N P O R PA R T I DAS PREPARACIÓN Y PRELIMINARES
A41: DEM5029 | B41: M1 | C41: 0.85120532 | D41: 33 | E41: DEMOLICIÓN DE MUROS INTERIORES DE TABICÓN DE 10 CM Y BLOCK DE 15 CM, MÁS EL MURO DE FACHADA DE 20 CM Y EL MURO POSTERIOR DE 16 CM DE LA VIVIENDA, A UNA ALTURA NO MAYOR A 3.40 METROS, CON MARTILLO DEMOLEDOR ELÉCTRICO Y HERRAMIENTA MANUAL. INCLUYE LEVANTADO DEL ESCOMBRO PRODUCTO DE LA DEMOLICIÓN Y SU ACOPIO DENTRO DE LA OBRA, RENTA DE EQUIPO, FLETE DE MAQUINARIA, HERRAMIENTA MENOR, MANO DE OBRA Y EQUIPO DE PROTECCIÓN PERSONAL. NO incluye los dos muros laterales ni el muro posterior del predio, que son compar- · tidos con las propiedades colindantes y se conservan. Los acabados, instalaciones, muebles, puertas y ventanas se demuelen junto con los muros y no se cuantifican por separado. | F41: DEMOLICIÓN DE MUROS INTERIORES DE TABICÓN DE 10 CM Y BLOCK DE 15 CM, MÁS EL MURO DE FACHADA DE 20 CM Y EL MURO POSTERIOR DE 16 CM DE LA VIVIENDA, A UNA ALTURA NO MAYOR A 3.40 METROS, CON MARTILLO DEMOLEDOR ELÉCTRICO Y HERRAMIENTA MANUAL. INCLUYE LEVANTADO DEL ESCOMBRO PRODUCTO DE LA DEMOLICIÓN Y SU ACOPIO DENTRO DE LA OBRA, RENTA DE EQUIPO, FLETE DE MAQUINARIA, HERRAMIENTA MENOR, MANO DE OBRA Y EQUIPO DE PROTECCIÓN PERSONAL. NO incluye los dos muros laterales ni el muro posterior del predio, que son compar-
...

Sheet TPU
A1: TARJETAS DE PRECIOS UNITARIOS
A2: PROYECTO | C2: =CARATULA!$C$10
A3: CLIENTE | C3: =CARATULA!$C$12
A4: UBICACIÓN | C4: =CARATULA!$C$14
A5: EMPRESA | C5: =CARATULA!$C$19
A6: Un renglón por insumo. importe = (cantidad ÷ rendimiento) × costo unitario × (1 + % desperdicio)
A7: El COSTO DIRECTO de cada concepto se acumula abajo y es lo que debe capturarse como P.U. BASE en el PRESUPUESTO.
